## Docker commands used to build the application
# TODO: insert the docker build command
docker build -t techtrends .
 
## Docker commands used to run the application
# TODO: insert the docker run command
# we used same setup (same ubuntu server so we had to use different port number.)
docker run -d -p 7113:3113 techtrends
 
## Docker commands used to get the application logs
# TODO: insert the docker logs command
#docker container

#docker ps -q
#3d1d6ff215f8

docker logs 3d1d6ff215f8


jaechul@goku:~/nd064_course_1/project/techtrends$ docker logs 3d1d6ff215f8
 * Serving Flask app 'app' (lazy loading)
 * Environment: production
   WARNING: This is a development server. Do not use it in a production deployment.
   Use a production WSGI server instead.
 * Debug mode: off


INFO:werkzeug: * Running on http://10.166.20.84:3113/ (Press CTRL+C to quit)
INFO:werkzeug:10.226.40.141 - - [01/Jun/2024 00:04:20] "GET /healthz HTTP/1.1" 200 -
ERROR:app:Exception on / [GET]
Traceback (most recent call last):
  File "/home/jaechul/nd064_course_1/venv_cloud/lib/python3.8/site-packages/flask/app.py", line 2077, in wsgi_app
    response = self.full_dispatch_request()
  File "/home/jaechul/nd064_course_1/venv_cloud/lib/python3.8/site-packages/flask/app.py", line 1525, in full_dispatch_request
    rv = self.handle_user_exception(e)
  File "/home/jaechul/nd064_course_1/venv_cloud/lib/python3.8/site-packages/flask/app.py", line 1523, in full_dispatch_request
    rv = self.dispatch_request()
  File "/home/jaechul/nd064_course_1/venv_cloud/lib/python3.8/site-packages/flask/app.py", line 1509, in dispatch_request
    return self.ensure_sync(self.view_functions[rule.endpoint])(**req.view_args)
  File "app.py", line 59, in index
    posts = connection.execute('SELECT * FROM posts').fetchall()
sqlite3.OperationalError: no such table: posts
INFO:werkzeug:10.226.40.141 - - [01/Jun/2024 00:04:25] "[35m[1mGET / HTTP/1.1[0m" 500 -
INFO:werkzeug:10.226.40.141 - - [01/Jun/2024 00:04:25] "[33mGET /favicon.ico HTTP/1.1[0m" 404 -
WARNING:werkzeug: * Running on all addresses.
   WARNING: This is a development server. Do not use it in a production deployment.
INFO:werkzeug: * Running on http://10.166.20.84:3113/ (Press CTRL+C to quit)
ERROR:app:Exception on / [GET]
Traceback (most recent call last):
  File "/home/jaechul/nd064_course_1/venv_cloud/lib/python3.8/site-packages/flask/app.py", line 2077, in wsgi_app
    response = self.full_dispatch_request()
  File "/home/jaechul/nd064_course_1/venv_cloud/lib/python3.8/site-packages/flask/app.py", line 1525, in full_dispatch_request
    rv = self.handle_user_exception(e)
  File "/home/jaechul/nd064_course_1/venv_cloud/lib/python3.8/site-packages/flask/app.py", line 1523, in full_dispatch_request
    rv = self.dispatch_request()
  File "/home/jaechul/nd064_course_1/venv_cloud/lib/python3.8/site-packages/flask/app.py", line 1509, in dispatch_request
    return self.ensure_sync(self.view_functions[rule.endpoint])(**req.view_args)
  File "app.py", line 59, in index
    posts = connection.execute('SELECT * FROM posts').fetchall()
sqlite3.OperationalError: no such table: posts
INFO:werkzeug:10.226.40.141 - - [01/Jun/2024 00:04:52] "[35m[1mGET / HTTP/1.1[0m" 500 -
INFO:werkzeug:10.226.40.141 - - [01/Jun/2024 00:04:55] "GET /healthz HTTP/1.1" 200 -
ERROR:app:Exception on /metrics [GET]
Traceback (most recent call last):
  File "/home/jaechul/nd064_course_1/venv_cloud/lib/python3.8/site-packages/flask/app.py", line 2077, in wsgi_app
    response = self.full_dispatch_request()
  File "/home/jaechul/nd064_course_1/venv_cloud/lib/python3.8/site-packages/flask/app.py", line 1525, in full_dispatch_request
    rv = self.handle_user_exception(e)
  File "/home/jaechul/nd064_course_1/venv_cloud/lib/python3.8/site-packages/flask/app.py", line 1523, in full_dispatch_request
    rv = self.dispatch_request()
  File "/home/jaechul/nd064_course_1/venv_cloud/lib/python3.8/site-packages/flask/app.py", line 1509, in dispatch_request
    return self.ensure_sync(self.view_functions[rule.endpoint])(**req.view_args)
  File "app.py", line 44, in metrics
    posts = connect.execute('SELECT * FROM posts').fetchall()
sqlite3.OperationalError: no such table: posts
INFO:werkzeug:10.226.40.141 - - [01/Jun/2024 00:05:13] "[35m[1mGET /metrics HTTP/1.1[0m" 500 -
WARNING:werkzeug: * Running on all addresses.
   WARNING: This is a development server. Do not use it in a production deployment.
INFO:werkzeug: * Running on http://10.166.20.84:3113/ (Press CTRL+C to quit)
ERROR:app:Exception on / [GET]
Traceback (most recent call last):
  File "/home/jaechul/nd064_course_1/venv_cloud/lib/python3.8/site-packages/flask/app.py", line 2077, in wsgi_app
    response = self.full_dispatch_request()
  File "/home/jaechul/nd064_course_1/venv_cloud/lib/python3.8/site-packages/flask/app.py", line 1525, in full_dispatch_request
    rv = self.handle_user_exception(e)
  File "/home/jaechul/nd064_course_1/venv_cloud/lib/python3.8/site-packages/flask/app.py", line 1523, in full_dispatch_request
    rv = self.dispatch_request()
  File "/home/jaechul/nd064_course_1/venv_cloud/lib/python3.8/site-packages/flask/app.py", line 1509, in dispatch_request
    return self.ensure_sync(self.view_functions[rule.endpoint])(**req.view_args)
  File "app.py", line 59, in index
    posts = connection.execute('SELECT * FROM posts').fetchall()
sqlite3.OperationalError: no such table: posts
INFO:werkzeug:10.226.40.141 - - [01/Jun/2024 00:12:08] "[35m[1mGET / HTTP/1.1[0m" 500 -
