WARNING:werkzeug: * Running on all addresses.
   WARNING: This is a development server. Do not use it in a production deployment.
INFO:werkzeug: * Running on http://10.166.20.84:3112/ (Press CTRL+C to quit)
ERROR:app:Exception on / [GET]
Traceback (most recent call last):
  File "/home/jaechul/nd064_course_1/venv_cloud/lib/python3.8/site-packages/flask/app.py", line 2077, in wsgi_app
    response = self.full_dispatch_request()
  File "/home/jaechul/nd064_course_1/venv_cloud/lib/python3.8/site-packages/flask/app.py", line 1525, in full_dispatch_request
    rv = self.handle_user_exception(e)
  File "/home/jaechul/nd064_course_1/venv_cloud/lib/python3.8/site-packages/flask/app.py", line 1523, in full_dispatch_request
    rv = self.dispatch_request()
  File "/home/jaechul/nd064_course_1/venv_cloud/lib/python3.8/site-packages/flask/app.py", line 1509, in dispatch_request
    return self.ensure_sync(self.view_functions[rule.endpoint])(**req.view_args)
  File "app.py", line 33, in index
    posts = connection.execute('SELECT * FROM posts').fetchall()
sqlite3.OperationalError: no such table: posts
INFO:werkzeug:10.226.40.141 - - [31/May/2024 23:16:19] "[35m[1mGET / HTTP/1.1[0m" 500 -
INFO:werkzeug:10.226.40.141 - - [31/May/2024 23:16:20] "[33mGET /favicon.ico HTTP/1.1[0m" 404 -
ERROR:app:Exception on / [GET]
Traceback (most recent call last):
  File "/home/jaechul/nd064_course_1/venv_cloud/lib/python3.8/site-packages/flask/app.py", line 2077, in wsgi_app
    response = self.full_dispatch_request()
  File "/home/jaechul/nd064_course_1/venv_cloud/lib/python3.8/site-packages/flask/app.py", line 1525, in full_dispatch_request
    rv = self.handle_user_exception(e)
  File "/home/jaechul/nd064_course_1/venv_cloud/lib/python3.8/site-packages/flask/app.py", line 1523, in full_dispatch_request
    rv = self.dispatch_request()
  File "/home/jaechul/nd064_course_1/venv_cloud/lib/python3.8/site-packages/flask/app.py", line 1509, in dispatch_request
    return self.ensure_sync(self.view_functions[rule.endpoint])(**req.view_args)
  File "app.py", line 33, in index
    posts = connection.execute('SELECT * FROM posts').fetchall()
sqlite3.OperationalError: no such table: posts
INFO:werkzeug:10.226.40.141 - - [31/May/2024 23:16:22] "[35m[1mGET / HTTP/1.1[0m" 500 -
WARNING:werkzeug: * Running on all addresses.
   WARNING: This is a development server. Do not use it in a production deployment.
INFO:werkzeug: * Running on http://10.166.20.84:3112/ (Press CTRL+C to quit)
ERROR:app:Exception on / [GET]
Traceback (most recent call last):
  File "/home/jaechul/nd064_course_1/venv_cloud/lib/python3.8/site-packages/flask/app.py", line 2077, in wsgi_app
    response = self.full_dispatch_request()
  File "/home/jaechul/nd064_course_1/venv_cloud/lib/python3.8/site-packages/flask/app.py", line 1525, in full_dispatch_request
    rv = self.handle_user_exception(e)
  File "/home/jaechul/nd064_course_1/venv_cloud/lib/python3.8/site-packages/flask/app.py", line 1523, in full_dispatch_request
    rv = self.dispatch_request()
  File "/home/jaechul/nd064_course_1/venv_cloud/lib/python3.8/site-packages/flask/app.py", line 1509, in dispatch_request
    return self.ensure_sync(self.view_functions[rule.endpoint])(**req.view_args)
  File "app.py", line 33, in index
    posts = connection.execute('SELECT * FROM posts').fetchall()
sqlite3.OperationalError: no such table: posts
INFO:werkzeug:10.226.40.141 - - [31/May/2024 23:16:56] "[35m[1mGET / HTTP/1.1[0m" 500 -
ERROR:app:Exception on / [GET]
Traceback (most recent call last):
  File "/home/jaechul/nd064_course_1/venv_cloud/lib/python3.8/site-packages/flask/app.py", line 2077, in wsgi_app
    response = self.full_dispatch_request()
  File "/home/jaechul/nd064_course_1/venv_cloud/lib/python3.8/site-packages/flask/app.py", line 1525, in full_dispatch_request
    rv = self.handle_user_exception(e)
  File "/home/jaechul/nd064_course_1/venv_cloud/lib/python3.8/site-packages/flask/app.py", line 1523, in full_dispatch_request
    rv = self.dispatch_request()
  File "/home/jaechul/nd064_course_1/venv_cloud/lib/python3.8/site-packages/flask/app.py", line 1509, in dispatch_request
    return self.ensure_sync(self.view_functions[rule.endpoint])(**req.view_args)
  File "app.py", line 33, in index
    posts = connection.execute('SELECT * FROM posts').fetchall()
sqlite3.OperationalError: no such table: posts
INFO:werkzeug:10.226.40.141 - - [31/May/2024 23:16:58] "[35m[1mGET / HTTP/1.1[0m" 500 -
WARNING:werkzeug: * Running on all addresses.
   WARNING: This is a development server. Do not use it in a production deployment.
INFO:werkzeug: * Running on http://10.166.20.84:3112/ (Press CTRL+C to quit)
ERROR:app:Exception on / [GET]
Traceback (most recent call last):
  File "/home/jaechul/nd064_course_1/venv_cloud/lib/python3.8/site-packages/flask/app.py", line 2077, in wsgi_app
    response = self.full_dispatch_request()
  File "/home/jaechul/nd064_course_1/venv_cloud/lib/python3.8/site-packages/flask/app.py", line 1525, in full_dispatch_request
    rv = self.handle_user_exception(e)
  File "/home/jaechul/nd064_course_1/venv_cloud/lib/python3.8/site-packages/flask/app.py", line 1523, in full_dispatch_request
    rv = self.dispatch_request()
  File "/home/jaechul/nd064_course_1/venv_cloud/lib/python3.8/site-packages/flask/app.py", line 1509, in dispatch_request
    return self.ensure_sync(self.view_functions[rule.endpoint])(**req.view_args)
  File "app.py", line 33, in index
    posts = connection.execute('SELECT * FROM posts').fetchall()
sqlite3.OperationalError: no such table: posts
INFO:werkzeug:10.226.40.141 - - [31/May/2024 23:17:29] "[35m[1mGET / HTTP/1.1[0m" 500 -
WARNING:werkzeug: * Running on all addresses.
   WARNING: This is a development server. Do not use it in a production deployment.
INFO:werkzeug: * Running on http://10.166.20.84:3111/ (Press CTRL+C to quit)
ERROR:app:Exception on / [GET]
Traceback (most recent call last):
  File "/home/jaechul/nd064_course_1/venv_cloud/lib/python3.8/site-packages/flask/app.py", line 2077, in wsgi_app
    response = self.full_dispatch_request()
  File "/home/jaechul/nd064_course_1/venv_cloud/lib/python3.8/site-packages/flask/app.py", line 1525, in full_dispatch_request
    rv = self.handle_user_exception(e)
  File "/home/jaechul/nd064_course_1/venv_cloud/lib/python3.8/site-packages/flask/app.py", line 1523, in full_dispatch_request
    rv = self.dispatch_request()
  File "/home/jaechul/nd064_course_1/venv_cloud/lib/python3.8/site-packages/flask/app.py", line 1509, in dispatch_request
    return self.ensure_sync(self.view_functions[rule.endpoint])(**req.view_args)
  File "app.py", line 33, in index
    posts = connection.execute('SELECT * FROM posts').fetchall()
sqlite3.OperationalError: no such table: posts
INFO:werkzeug:10.226.40.141 - - [31/May/2024 23:18:00] "[35m[1mGET / HTTP/1.1[0m" 500 -
INFO:werkzeug:10.226.40.141 - - [31/May/2024 23:18:00] "[33mGET /favicon.ico HTTP/1.1[0m" 404 -
ERROR:app:Exception on / [GET]
Traceback (most recent call last):
  File "/home/jaechul/nd064_course_1/venv_cloud/lib/python3.8/site-packages/flask/app.py", line 2077, in wsgi_app
    response = self.full_dispatch_request()
  File "/home/jaechul/nd064_course_1/venv_cloud/lib/python3.8/site-packages/flask/app.py", line 1525, in full_dispatch_request
    rv = self.handle_user_exception(e)
  File "/home/jaechul/nd064_course_1/venv_cloud/lib/python3.8/site-packages/flask/app.py", line 1523, in full_dispatch_request
    rv = self.dispatch_request()
  File "/home/jaechul/nd064_course_1/venv_cloud/lib/python3.8/site-packages/flask/app.py", line 1509, in dispatch_request
    return self.ensure_sync(self.view_functions[rule.endpoint])(**req.view_args)
  File "app.py", line 33, in index
    posts = connection.execute('SELECT * FROM posts').fetchall()
sqlite3.OperationalError: no such table: posts
INFO:werkzeug:10.226.40.141 - - [31/May/2024 23:18:01] "[35m[1mGET / HTTP/1.1[0m" 500 -
ERROR:app:Exception on / [GET]
Traceback (most recent call last):
  File "/home/jaechul/nd064_course_1/venv_cloud/lib/python3.8/site-packages/flask/app.py", line 2077, in wsgi_app
    response = self.full_dispatch_request()
  File "/home/jaechul/nd064_course_1/venv_cloud/lib/python3.8/site-packages/flask/app.py", line 1525, in full_dispatch_request
    rv = self.handle_user_exception(e)
  File "/home/jaechul/nd064_course_1/venv_cloud/lib/python3.8/site-packages/flask/app.py", line 1523, in full_dispatch_request
    rv = self.dispatch_request()
  File "/home/jaechul/nd064_course_1/venv_cloud/lib/python3.8/site-packages/flask/app.py", line 1509, in dispatch_request
    return self.ensure_sync(self.view_functions[rule.endpoint])(**req.view_args)
  File "app.py", line 33, in index
    posts = connection.execute('SELECT * FROM posts').fetchall()
sqlite3.OperationalError: no such table: posts
INFO:werkzeug:10.226.40.141 - - [31/May/2024 23:18:20] "[35m[1mGET / HTTP/1.1[0m" 500 -
ERROR:app:Exception on / [GET]
Traceback (most recent call last):
  File "/home/jaechul/nd064_course_1/venv_cloud/lib/python3.8/site-packages/flask/app.py", line 2077, in wsgi_app
    response = self.full_dispatch_request()
  File "/home/jaechul/nd064_course_1/venv_cloud/lib/python3.8/site-packages/flask/app.py", line 1525, in full_dispatch_request
    rv = self.handle_user_exception(e)
  File "/home/jaechul/nd064_course_1/venv_cloud/lib/python3.8/site-packages/flask/app.py", line 1523, in full_dispatch_request
    rv = self.dispatch_request()
  File "/home/jaechul/nd064_course_1/venv_cloud/lib/python3.8/site-packages/flask/app.py", line 1509, in dispatch_request
    return self.ensure_sync(self.view_functions[rule.endpoint])(**req.view_args)
  File "app.py", line 33, in index
    posts = connection.execute('SELECT * FROM posts').fetchall()
sqlite3.OperationalError: no such table: posts
INFO:werkzeug:10.226.92.188 - - [31/May/2024 23:18:26] "[35m[1mGET / HTTP/1.1[0m" 500 -
INFO:werkzeug:10.226.92.188 - - [31/May/2024 23:18:27] "[33mGET /favicon.ico HTTP/1.1[0m" 404 -
ERROR:app:Exception on / [GET]
Traceback (most recent call last):
  File "/home/jaechul/nd064_course_1/venv_cloud/lib/python3.8/site-packages/flask/app.py", line 2077, in wsgi_app
    response = self.full_dispatch_request()
  File "/home/jaechul/nd064_course_1/venv_cloud/lib/python3.8/site-packages/flask/app.py", line 1525, in full_dispatch_request
    rv = self.handle_user_exception(e)
  File "/home/jaechul/nd064_course_1/venv_cloud/lib/python3.8/site-packages/flask/app.py", line 1523, in full_dispatch_request
    rv = self.dispatch_request()
  File "/home/jaechul/nd064_course_1/venv_cloud/lib/python3.8/site-packages/flask/app.py", line 1509, in dispatch_request
    return self.ensure_sync(self.view_functions[rule.endpoint])(**req.view_args)
  File "app.py", line 33, in index
    posts = connection.execute('SELECT * FROM posts').fetchall()
sqlite3.OperationalError: no such table: posts
INFO:werkzeug:10.226.40.141 - - [31/May/2024 23:19:03] "[35m[1mGET / HTTP/1.1[0m" 500 -
WARNING:werkzeug: * Running on all addresses.
   WARNING: This is a development server. Do not use it in a production deployment.
INFO:werkzeug: * Running on http://10.166.20.84:3112/ (Press CTRL+C to quit)
WARNING:werkzeug: * Running on all addresses.
   WARNING: This is a development server. Do not use it in a production deployment.
INFO:werkzeug: * Running on http://10.166.20.84:3113/ (Press CTRL+C to quit)
INFO:werkzeug:10.226.40.141 - - [01/Jun/2024 00:04:20] "GET /healthz HTTP/1.1" 200 -
ERROR:app:Exception on / [GET]
Traceback (most recent call last):
  File "/home/jaechul/nd064_course_1/venv_cloud/lib/python3.8/site-packages/flask/app.py", line 2077, in wsgi_app
    response = self.full_dispatch_request()
  File "/home/jaechul/nd064_course_1/venv_cloud/lib/python3.8/site-packages/flask/app.py", line 1525, in full_dispatch_request
    rv = self.handle_user_exception(e)
  File "/home/jaechul/nd064_course_1/venv_cloud/lib/python3.8/site-packages/flask/app.py", line 1523, in full_dispatch_request
    rv = self.dispatch_request()
  File "/home/jaechul/nd064_course_1/venv_cloud/lib/python3.8/site-packages/flask/app.py", line 1509, in dispatch_request
    return self.ensure_sync(self.view_functions[rule.endpoint])(**req.view_args)
  File "app.py", line 59, in index
    posts = connection.execute('SELECT * FROM posts').fetchall()
sqlite3.OperationalError: no such table: posts
INFO:werkzeug:10.226.40.141 - - [01/Jun/2024 00:04:25] "[35m[1mGET / HTTP/1.1[0m" 500 -
INFO:werkzeug:10.226.40.141 - - [01/Jun/2024 00:04:25] "[33mGET /favicon.ico HTTP/1.1[0m" 404 -
WARNING:werkzeug: * Running on all addresses.
   WARNING: This is a development server. Do not use it in a production deployment.
INFO:werkzeug: * Running on http://10.166.20.84:3113/ (Press CTRL+C to quit)
ERROR:app:Exception on / [GET]
Traceback (most recent call last):
  File "/home/jaechul/nd064_course_1/venv_cloud/lib/python3.8/site-packages/flask/app.py", line 2077, in wsgi_app
    response = self.full_dispatch_request()
  File "/home/jaechul/nd064_course_1/venv_cloud/lib/python3.8/site-packages/flask/app.py", line 1525, in full_dispatch_request
    rv = self.handle_user_exception(e)
  File "/home/jaechul/nd064_course_1/venv_cloud/lib/python3.8/site-packages/flask/app.py", line 1523, in full_dispatch_request
    rv = self.dispatch_request()
  File "/home/jaechul/nd064_course_1/venv_cloud/lib/python3.8/site-packages/flask/app.py", line 1509, in dispatch_request
    return self.ensure_sync(self.view_functions[rule.endpoint])(**req.view_args)
  File "app.py", line 59, in index
    posts = connection.execute('SELECT * FROM posts').fetchall()
sqlite3.OperationalError: no such table: posts
INFO:werkzeug:10.226.40.141 - - [01/Jun/2024 00:04:52] "[35m[1mGET / HTTP/1.1[0m" 500 -
INFO:werkzeug:10.226.40.141 - - [01/Jun/2024 00:04:55] "GET /healthz HTTP/1.1" 200 -
ERROR:app:Exception on /metrics [GET]
Traceback (most recent call last):
  File "/home/jaechul/nd064_course_1/venv_cloud/lib/python3.8/site-packages/flask/app.py", line 2077, in wsgi_app
    response = self.full_dispatch_request()
  File "/home/jaechul/nd064_course_1/venv_cloud/lib/python3.8/site-packages/flask/app.py", line 1525, in full_dispatch_request
    rv = self.handle_user_exception(e)
  File "/home/jaechul/nd064_course_1/venv_cloud/lib/python3.8/site-packages/flask/app.py", line 1523, in full_dispatch_request
    rv = self.dispatch_request()
  File "/home/jaechul/nd064_course_1/venv_cloud/lib/python3.8/site-packages/flask/app.py", line 1509, in dispatch_request
    return self.ensure_sync(self.view_functions[rule.endpoint])(**req.view_args)
  File "app.py", line 44, in metrics
    posts = connect.execute('SELECT * FROM posts').fetchall()
sqlite3.OperationalError: no such table: posts
INFO:werkzeug:10.226.40.141 - - [01/Jun/2024 00:05:13] "[35m[1mGET /metrics HTTP/1.1[0m" 500 -
WARNING:werkzeug: * Running on all addresses.
   WARNING: This is a development server. Do not use it in a production deployment.
INFO:werkzeug: * Running on http://10.166.20.84:3113/ (Press CTRL+C to quit)
ERROR:app:Exception on / [GET]
Traceback (most recent call last):
  File "/home/jaechul/nd064_course_1/venv_cloud/lib/python3.8/site-packages/flask/app.py", line 2077, in wsgi_app
    response = self.full_dispatch_request()
  File "/home/jaechul/nd064_course_1/venv_cloud/lib/python3.8/site-packages/flask/app.py", line 1525, in full_dispatch_request
    rv = self.handle_user_exception(e)
  File "/home/jaechul/nd064_course_1/venv_cloud/lib/python3.8/site-packages/flask/app.py", line 1523, in full_dispatch_request
    rv = self.dispatch_request()
  File "/home/jaechul/nd064_course_1/venv_cloud/lib/python3.8/site-packages/flask/app.py", line 1509, in dispatch_request
    return self.ensure_sync(self.view_functions[rule.endpoint])(**req.view_args)
  File "app.py", line 59, in index
    posts = connection.execute('SELECT * FROM posts').fetchall()
sqlite3.OperationalError: no such table: posts
INFO:werkzeug:10.226.40.141 - - [01/Jun/2024 00:12:08] "[35m[1mGET / HTTP/1.1[0m" 500 -
